<?xml version="1.0" ?>
<!-- =================================================================================== -->
<!-- |    This document was autogenerated by xacro from /home/jun/jackal_ws/src/jackal/jackal_description/sdf/jackal.sdf.xacro | -->
<!-- |    EDITING THIS FILE BY HAND IS NOT RECOMMENDED                                 | -->
<!-- =================================================================================== -->
<sdf version="1.7">
  <model canonical_link="base_link" name="jackal">
    <plugin filename="libignition-gazebo-joint-state-publisher-system.so" name="ignition::gazebo::systems::JointStatePublisher">
    </plugin>
    <!-- Base and Chassis -->
    <link name="base_link">
      <pose relative_to="__model__">0 0 0 0 0 0</pose>
    </link>
    <link name="chassis_link">
      <pose relative_to="base_link_joint">0 0 0.0655 0 0 0</pose>
      <visual name="chassis_visual">
        <geometry>
          <mesh>
            <uri>model://jackal_description/meshes/jackal-base.stl</uri>
          </mesh>
        </geometry>
        <material>
          <ambient>0.2 0.2 0.2 1.0</ambient>
          <diffuse>0.2 0.2 0.2 1.0</diffuse>
        </material>
        <pose>0 0 -0.0655 1.5707963267948966 0 1.5707963267948966</pose>
      </visual>
      <collision name="chassis_collision">
        <geometry>
          <box>
            <size>0.42 0.31 0.184</size>
          </box>
        </geometry>
        <pose>0 0 0.092 0 0 0</pose>
      </collision>
      <inertial>
        <mass>16.523</mass>
        <pose>0.012 0.002 0.067 0 0 0</pose>
        <inertia>
          <ixx>0.3136</ixx>
          <ixy>-0.0008</ixy>
          <ixz>0.0164</ixz>
          <iyy>0.3922</iyy>
          <iyz>-0.0009</iyz>
          <izz>0.4485</izz>
        </inertia>
      </inertial>
    </link>
    <joint name="base_link_joint" type="fixed">
      <parent>base_link</parent>
      <child>chassis_link</child>
      <pose relative_to="base_link">0 0 0 0 0 0</pose>
    </joint>
    <link name="front_left_wheel_link">
      <pose relative_to="front_left_wheel_joint">0 0 0 0 0 0</pose>
      <visual name="front_left_wheel_visual">
        <pose>0 0 0 1.5707963267948966 0 0</pose>
        <geometry>
          <mesh>
            <uri>model://jackal_description/meshes/jackal-wheel.stl</uri>
          </mesh>
        </geometry>
        <material>
          <ambient>0.15 0.15 0.15 1.0</ambient>
          <diffuse>0.15 0.15 0.15 1.0</diffuse>
        </material>
      </visual>
      <collision name="front_left_wheel_collision">
        <pose>0 0 0 1.5707963267948966 0 0</pose>
        <geometry>
          <cylinder>
            <radius>0.098</radius>
            <length>0.04</length>
          </cylinder>
        </geometry>
      </collision>
      <inertial>
        <mass>0.477</mass>
        <pose>0 0 0 0 0 0</pose>
        <inertia>
          <ixx>0.0013</ixx>
          <ixy>0</ixy>
          <ixz>0</ixz>
          <iyy>0.0024</iyy>
          <iyz>0</iyz>
          <izz>0.0013</izz>
        </inertia>
      </inertial>
    </link>
    <joint name="front_left_wheel_joint" type="revolute">
      <parent>chassis_link</parent>
      <child>front_left_wheel_link</child>
      <pose relative_to="chassis_link">0.131 0.187795 0.0345 0 0 0</pose>
      <axis>
        <xyz expressed_in="__model__">0 1 0</xyz>
      </axis>
      <dynamics>
        <damping>0.0</damping>
      </dynamics>
    </joint>
    <link name="front_right_wheel_link">
      <pose relative_to="front_right_wheel_joint">0 0 0 0 0 0</pose>
      <visual name="front_right_wheel_visual">
        <pose>0 0 0 1.5707963267948966 0 0</pose>
        <geometry>
          <mesh>
            <uri>model://jackal_description/meshes/jackal-wheel.stl</uri>
          </mesh>
        </geometry>
        <material>
          <ambient>0.15 0.15 0.15 1.0</ambient>
          <diffuse>0.15 0.15 0.15 1.0</diffuse>
        </material>
      </visual>
      <collision name="front_right_wheel_collision">
        <pose>0 0 0 1.5707963267948966 0 0</pose>
        <geometry>
          <cylinder>
            <radius>0.098</radius>
            <length>0.04</length>
          </cylinder>
        </geometry>
      </collision>
      <inertial>
        <mass>0.477</mass>
        <pose>0 0 0 0 0 0</pose>
        <inertia>
          <ixx>0.0013</ixx>
          <ixy>0</ixy>
          <ixz>0</ixz>
          <iyy>0.0024</iyy>
          <iyz>0</iyz>
          <izz>0.0013</izz>
        </inertia>
      </inertial>
    </link>
    <joint name="front_right_wheel_joint" type="revolute">
      <parent>chassis_link</parent>
      <child>front_right_wheel_link</child>
      <pose relative_to="chassis_link">0.131 -0.187795 0.0345 0 0 0</pose>
      <axis>
        <xyz expressed_in="__model__">0 1 0</xyz>
      </axis>
      <dynamics>
        <damping>0.0</damping>
      </dynamics>
    </joint>
    <link name="rear_left_wheel_link">
      <pose relative_to="rear_left_wheel_joint">0 0 0 0 0 0</pose>
      <visual name="rear_left_wheel_visual">
        <pose>0 0 0 1.5707963267948966 0 0</pose>
        <geometry>
          <mesh>
            <uri>model://jackal_description/meshes/jackal-wheel.stl</uri>
          </mesh>
        </geometry>
        <material>
          <ambient>0.15 0.15 0.15 1.0</ambient>
          <diffuse>0.15 0.15 0.15 1.0</diffuse>
        </material>
      </visual>
      <collision name="rear_left_wheel_collision">
        <pose>0 0 0 1.5707963267948966 0 0</pose>
        <geometry>
          <cylinder>
            <radius>0.098</radius>
            <length>0.04</length>
          </cylinder>
        </geometry>
      </collision>
      <inertial>
        <mass>0.477</mass>
        <pose>0 0 0 0 0 0</pose>
        <inertia>
          <ixx>0.0013</ixx>
          <ixy>0</ixy>
          <ixz>0</ixz>
          <iyy>0.0024</iyy>
          <iyz>0</iyz>
          <izz>0.0013</izz>
        </inertia>
      </inertial>
    </link>
    <joint name="rear_left_wheel_joint" type="revolute">
      <parent>chassis_link</parent>
      <child>rear_left_wheel_link</child>
      <pose relative_to="chassis_link">-0.131 0.187795 0.0345 0 0 0</pose>
      <axis>
        <xyz expressed_in="__model__">0 1 0</xyz>
      </axis>
      <dynamics>
        <damping>0.0</damping>
      </dynamics>
    </joint>
    <link name="rear_right_wheel_link">
      <pose relative_to="rear_right_wheel_joint">0 0 0 0 0 0</pose>
      <visual name="rear_right_wheel_visual">
        <pose>0 0 0 1.5707963267948966 0 0</pose>
        <geometry>
          <mesh>
            <uri>model://jackal_description/meshes/jackal-wheel.stl</uri>
          </mesh>
        </geometry>
        <material>
          <ambient>0.15 0.15 0.15 1.0</ambient>
          <diffuse>0.15 0.15 0.15 1.0</diffuse>
        </material>
      </visual>
      <collision name="rear_right_wheel_collision">
        <pose>0 0 0 1.5707963267948966 0 0</pose>
        <geometry>
          <cylinder>
            <radius>0.098</radius>
            <length>0.04</length>
          </cylinder>
        </geometry>
      </collision>
      <inertial>
        <mass>0.477</mass>
        <pose>0 0 0 0 0 0</pose>
        <inertia>
          <ixx>0.0013</ixx>
          <ixy>0</ixy>
          <ixz>0</ixz>
          <iyy>0.0024</iyy>
          <iyz>0</iyz>
          <izz>0.0013</izz>
        </inertia>
      </inertial>
    </link>
    <joint name="rear_right_wheel_joint" type="revolute">
      <parent>chassis_link</parent>
      <child>rear_right_wheel_link</child>
      <pose relative_to="chassis_link">-0.131 -0.187795 0.0345 0 0 0</pose>
      <axis>
        <xyz expressed_in="__model__">0 1 0</xyz>
      </axis>
      <dynamics>
        <damping>0.0</damping>
      </dynamics>
    </joint>
    <plugin filename="libignition-gazebo-diff-drive-system.so" name="ignition::gazebo::systems::DiffDrive">
      <left_joint>rear_left_wheel_joint</left_joint>
      <left_joint>front_left_wheel_joint</left_joint>
      <right_joint>rear_right_wheel_joint</right_joint>
      <right_joint>front_right_wheel_joint</right_joint>
      <wheel_separation>0.37559</wheel_separation>
      <wheel_radius>0.098</wheel_radius>
      <topic>/cmd_vel</topic>
      <odometry_topic>odom</odometry_topic>
      <publish_odom>true</publish_odom>
      <publish_tf>true</publish_tf>
    </plugin>
    <!-- Front Fender -->
    <link name="front_fender_link">
      <pose relative_to="front_fender_joint">0 0 0 0 0 0</pose>
      <visual name="front_fender_visual">
        <geometry>
          <mesh>
            <uri>model://jackal_description/meshes/jackal-fender.stl</uri>
          </mesh>
        </geometry>
        <material>
          <ambient>0.8 0.8 0.0 1.0</ambient>
          <diffuse>0.8 0.8 0.0 1.0</diffuse>
        </material>
      </visual>
    </link>
    <joint name="front_fender_joint" type="fixed">
      <parent>chassis_link</parent>
      <child>front_fender_link</child>
      <pose relative_to="chassis_link">0 0 0 0 0 0</pose>
    </joint>
    <!-- Rear Fender -->
    <link name="rear_fender_link">
      <pose relative_to="rear_fender_joint">0 0 0 0 0 0</pose>
      <visual name="rear_fender_visual">
        <geometry>
          <mesh>
            <uri>model://jackal_description/meshes/jackal-fender.stl</uri>
          </mesh>
        </geometry>
        <material>
          <ambient>0.8 0.8 0.0 1.0</ambient>
          <diffuse>0.8 0.8 0.0 1.0</diffuse>
        </material>
      </visual>
    </link>
    <joint name="rear_fender_joint" type="fixed">
      <parent>chassis_link</parent>
      <child>rear_fender_link</child>
      <pose relative_to="chassis_link">0 0 0 0 0 3.141592653589793</pose>
    </joint>
    <!-- IMU -->
    <link name="imu_link">
      <pose relative_to="imu_joint"> 0 0 0 0 0 0</pose>
      <inertial>
        <mass>0.001</mass>
        <pose>0 0 0 0 0 0</pose>
        <inertia>
          <ixx>1e-09</ixx>
          <ixy>0.0</ixy>
          <ixz>0.0</ixz>
          <iyy>1e-09</iyy>
          <iyz>0.0</iyz>
          <izz>1e-09</izz>
        </inertia>
      </inertial>
      <sensor name="imu_sensor" type="imu">
        <pose>0 0 0 0 0 0</pose>
        <always_on>true</always_on>
        <update_rate>100</update_rate>
        <imu>
          <angular_velocity>
            <x>
              <noise type="gaussian">
                <mean>0.0</mean>
                <stddev>0.005</stddev>
              </noise>
            </x>
            <y>
              <noise type="gaussian">
                <mean>0.0</mean>
                <stddev>0.005</stddev>
              </noise>
            </y>
            <z>
              <noise type="gaussian">
                <mean>0.0</mean>
                <stddev>0.005</stddev>
              </noise>
            </z>
          </angular_velocity>
          <linear_acceleration>
            <x>
              <noise type="gaussian">
                <mean>0.0</mean>
                <stddev>0.02</stddev>
              </noise>
            </x>
            <y>
              <noise type="gaussian">
                <mean>0.0</mean>
                <stddev>0.02</stddev>
              </noise>
            </y>
            <z>
              <noise type="gaussian">
                <mean>0.0</mean>
                <stddev>0.02</stddev>
              </noise>
            </z>
          </linear_acceleration>
        </imu>
      </sensor>
    </link>
    <joint name="imu_joint" type="fixed">
      <parent>chassis_link</parent>
      <child>imu_link</child>
      <pose relative_to="chassis_link">0 0 0 0 0 0</pose>
    </joint>
    <!-- Navsat -->
    <link name="navsat_link">
      <pose relative_to="navsat_joint"> 0 0 0 0 0 0</pose>
      <visual name="navsat_visual">
        <geometry>
          <cylinder>
            <radius>0.026</radius>
            <length>0.016</length>
          </cylinder>
        </geometry>
        <pose>0 0 0.008 0 0 0</pose>
        <material>
          <ambient>0.15 0.15 0.15 1.0</ambient>
          <diffuse>0.15 0.15 0.15 1.0</diffuse>
        </material>
      </visual>
      <sensor name="gps_sensor" type="navsat">
        <pose>0 0 0 0 0 0</pose>
        <always_on>true</always_on>
        <update_rate>10</update_rate>
      </sensor>
    </link>
    <joint name="navsat_joint" type="fixed">
      <parent>chassis_link</parent>
      <child>navsat_link</child>
      <pose relative_to="chassis_link">-0.180 0.126 0.1815 0 0 0</pose>
    </joint>
    <!-- Mounts -->
    <link name="mid_mount">
      <pose relative_to="mid_mount_joint">0 0 0 0 0 0</pose>
    </link>
    <joint name="mid_mount_joint" type="fixed">
      <parent>chassis_link</parent>
      <child>mid_mount</child>
      <pose relative_to="chassis_link">0 0 0.184 0 0 0</pose>
    </joint>
    <link name="rear_mount">
      <pose relative_to="rear_mount_joint">0 0 0 0 0 0</pose>
    </link>
    <joint name="rear_mount_joint" type="fixed">
      <parent>mid_mount</parent>
      <child>rear_mount</child>
      <pose relative_to="mid_mount">-0.12 0 0 0 0 0</pose>
    </joint>
    <link name="front_mount">
      <pose relative_to="front_mount_joint">0 0 0 0 0 0</pose>
    </link>
    <joint name="front_mount_joint" type="fixed">
      <parent>mid_mount</parent>
      <child>front_mount</child>
      <pose relative_to="mid_mount">0.12 0 0 0 0 0</pose>
    </joint>
    <!-- Fenders -->
    <!-- (unchanged content skipped for brevity) -->
    <!-- 지지대 링크 -->
    <link name="zed_mount_link">
      <pose relative_to="zed_mount_joint">0 0 0 0 0 0</pose>
      <visual name="zed_mount_visual">
        <pose>0 0 0 1.5707963267948966 0 1.5707963267948966</pose>
        <geometry>
          <mesh>
            <uri>model://jackal_description/meshes/support_v1_binary.stl</uri>
            <scale>0.001 0.001 0.001</scale>
          </mesh>
        </geometry>
        <material>
          <ambient>0.4 0.4 0.4 1</ambient>
          <diffuse>0.4 0.4 0.4 1</diffuse>
        </material>
      </visual>
      <collision name="zed_mount_collision">
        <pose>0 0 0 1.5707963267948966 0 1.5707963267948966</pose>
        <geometry>
          <mesh>
            <uri>model://jackal_description/meshes/support_v1_binary.stl</uri>
            <scale>0.001 0.001 0.001</scale>
          </mesh>
        </geometry>
      </collision>
      <inertial>
        <mass>0.3</mass>
        <pose>0 0 0.125 0 0 0</pose>
        <inertia>
          <ixx>0.001</ixx>
          <ixy>0.0</ixy>
          <ixz>0.0</ixz>
          <iyy>0.001</iyy>
          <iyz>0.0</iyz>
          <izz>0.001</izz>
        </inertia>
      </inertial>
    </link>
    <!-- ZED 2i 본체 -->
    <link name="zed_2i_link">
      <pose relative_to="zed_2i_base_joint">0 0 0 0 0 0</pose>
      <visual name="zed_2i_visual">
        <geometry>
          <mesh>
            <uri>model://jackal_description/meshes/ZED2i_binary.stl</uri>
            <scale>0.001 0.001 0.001</scale>
          </mesh>
        </geometry>
        <material>
          <ambient>0.1 0.1 0.1 1</ambient>
          <diffuse>0.1 0.1 0.1 1</diffuse>
        </material>
        <pose>-0.036262 0.008969 0.017741 0 0 1.5707963267948966</pose>
      </visual>
      <collision name="zed_2i_collision">
        <geometry>
          <box>
            <size>0.16 0.035 0.025</size>
          </box>
        </geometry>
        <pose>-0.0025 0 0.015 1.5707963267948966 0 1.5707963267948966</pose>
      </collision>
      <inertial>
        <mass>0.166</mass>
        <pose>0 0 0.015 0 0 0</pose>
        <inertia>
          <ixx>2.49e-05</ixx>
          <ixy>0</ixy>
          <ixz>0</ixz>
          <iyy>0.0002836</iyy>
          <iyz>0</iyz>
          <izz>0.0002836</izz>
        </inertia>
      </inertial>
    </link>
    <joint name="zed_2i_base_joint" type="fixed">
      <parent>zed_mount_link</parent>
      <child>zed_2i_link</child>
      <pose relative_to="zed_mount_link">0 0 0.25 0 0 0</pose>
    </joint>
    <!-- ZED 렌즈 센터 -->
    <link name="zed_2i_lens_center">
      <pose relative_to="zed_2i_lens_center_joint">0 0 0 0 0 0</pose>
    </link>
    <joint name="zed_2i_lens_center_joint" type="fixed">
      <parent>zed_2i_link</parent>
      <child>zed_2i_lens_center</child>
      <pose relative_to="zed_2i_link">0.012994 0 0.015309 -1.5707963267948966 0 -1.5707963267948966</pose>
    </joint>
    <!-- 좌우 렌즈 -->
    <link name="zed_2i_right_lens">
      <pose relative_to="zed_2i_right_lens_joint">0 0 0 0 0 0</pose>
    </link>
    <joint name="zed_2i_right_lens_joint" type="fixed">
      <parent>zed_2i_lens_center</parent>
      <child>zed_2i_right_lens</child>
      <pose relative_to="zed_2i_lens_center">0.06 0 0 0 0 0</pose>
    </joint>
    <link name="zed_2i_left_lens">
      <pose relative_to="zed_2i_left_lens_joint">0 0 0 0 0 0</pose>
    </link>
    <joint name="zed_2i_left_lens_joint" type="fixed">
      <parent>zed_2i_lens_center</parent>
      <child>zed_2i_left_lens</child>
      <pose relative_to="zed_2i_lens_center">-0.06 0 0 0 0 0</pose>
    </joint>
    <!-- 렌즈 Gazebo 용 링크 -->
    <link name="zed_2i_left_lens_gazebo">
      <pose relative_to="zed_2i_left_lens_joint_gazebo">0 0 0 0 0 0</pose>
      <sensor name="zed_depth_camera" type="depth">
        <pose>0 0 0 0 0 0</pose>
        <always_on>true</always_on>
        <update_rate>30</update_rate>
        <camera>
          <horizontal_fov>1.92</horizontal_fov>
          <image>
            <width>1280</width>
            <height>960</height>
            <format>R8G8B8</format>
          </image>
          <clip>
            <near>0.1</near>
            <far>20.0</far>
          </clip>
          <noise>
            <type>gaussian</type>
            <mean>0.0</mean>
            <stddev>0.005</stddev>
          </noise>
        </camera>
        <topic>zed_camera/depth_image</topic>
      </sensor>
      <sensor name="zed_rgb_camera" type="camera">
        <pose>0 0 0 0 0 0</pose>
        <!-- 렌즈 위치에 맞게 수정 -->
        <camera>
          <horizontal_fov>1.92</horizontal_fov>
          <image>
            <width>1280</width>
            <height>960</height>
            <format>R8G8B8</format>
          </image>
          <clip>
            <near>0.1</near>
            <far>20.0</far>
          </clip>
        </camera>
        <always_on>true</always_on>
        <update_rate>30</update_rate>
        <visualize>true</visualize>
        <topic>zed_camera/rgb_image</topic>
      </sensor>
    </link>
    <joint name="zed_2i_left_lens_joint_gazebo" type="fixed">
      <parent>zed_2i_left_lens</parent>
      <child>zed_2i_left_lens_gazebo</child>
      <pose relative_to="zed_2i_left_lens">0 0 0 1.5707963267948966 -1.5707963267948966 0</pose>
    </joint>
    <joint name="zed_mount_joint" type="fixed">
      <parent>mid_mount</parent>
      <child>zed_mount_link</child>
      <pose relative_to="mid_mount">0.06 0 0 0 0 0</pose>
    </joint>
  </model>
</sdf>
